<robot name="3DOF">
  <link name="base_link" />
  <link name="link1">
    <visual>
      <geometry>
        <cylinder length="0.5" radius="0.1"/>
      </geometry>
    </visual>
  </link>
  <link name="link2">
    <visual>
      <geometry>
        <cylinder length="0.5" radius="0.1"/>
      </geometry>
    </visual>
  </link>
  <link name="link3">
    <visual>
      <geometry>
        <cylinder length="0.3" radius="0.1"/>
      </geometry>
    </visual>
  </link>
  <link name="tcp">
    <visual>
      <geometry>
        <sphere radius="0.1"/>
      </geometry>
    </visual>
  </link>

  <joint name="joint1" type="revolute">
    <parent link="base_link"/>
    <child link="link1"/>
    <limit effort="99" velocity="99" lower="0" upper="3.141592653589793"/>
    <origin xyz="0 0 0" rpy="0 0 0"/>
    <axis xyz="0 0 1"/>
  </joint>

  <joint name="joint2" type="revolute">
    <parent link="link1"/>
    <child link="link2"/>
    <limit effort="99" velocity="99" lower="-1.5707963267948966" upper="1.5707963267948966"/>
    <origin xyz="0.5 0 0" rpy="0 0 0"/>
    <axis xyz="0 0 1"/>
  </joint>

  <joint name="joint3" type="revolute">
    <parent link="link2"/>
    <child link="link3"/>
    <limit effort="99" velocity="99" lower="-3.141592653589793" upper="3.141592653589793"/>
    <origin xyz="0.5 0 0" rpy="0 0 0"/>
    <axis xyz="0 0 1"/>
  </joint>
  
    <joint name="jointtcp" type="fixed">
    <parent link="link3"/>
    <child link="tcp"/>
    <origin xyz="0.3 0 0" rpy="0 0 0"/>
  </joint>
</robot>
